{
 "cells": [
  {
   "cell_type": "code",
   "execution_count": 2,
   "id": "b2ac5b89",
   "metadata": {},
   "outputs": [],
   "source": [
    "import mysql.connector\n",
    "from mysql.connector import Error"
   ]
  },
  {
   "cell_type": "code",
   "execution_count": 5,
   "id": "aa195bb8",
   "metadata": {},
   "outputs": [],
   "source": [
    "#Définition de variables de connexion\n",
    "user_teamprogffxiv = 'root'\n",
    "password_teamprogffxiv = 'ff14*fflogs*P@ss'\n",
    "host_teamprogffxiv = '127.0.0.1:3305'\n",
    "database_name = 'teamprogffxiv'"
   ]
  },
  {
   "cell_type": "code",
   "execution_count": 6,
   "id": "4068b9b3",
   "metadata": {},
   "outputs": [
    {
     "ename": "DatabaseError",
     "evalue": "2005 (HY000): Unknown MySQL server host '192.168.1.1:3305' (11001)",
     "output_type": "error",
     "traceback": [
      "\u001b[1;31m---------------------------------------------------------------------------\u001b[0m",
      "\u001b[1;31mMySQLInterfaceError\u001b[0m                       Traceback (most recent call last)",
      "\u001b[1;32mD:\\Anaconda\\lib\\site-packages\\mysql\\connector\\connection_cext.py\u001b[0m in \u001b[0;36m_open_connection\u001b[1;34m(self)\u001b[0m\n\u001b[0;32m    287\u001b[0m         \u001b[1;32mtry\u001b[0m\u001b[1;33m:\u001b[0m\u001b[1;33m\u001b[0m\u001b[1;33m\u001b[0m\u001b[0m\n\u001b[1;32m--> 288\u001b[1;33m             \u001b[0mself\u001b[0m\u001b[1;33m.\u001b[0m\u001b[0m_cmysql\u001b[0m\u001b[1;33m.\u001b[0m\u001b[0mconnect\u001b[0m\u001b[1;33m(\u001b[0m\u001b[1;33m**\u001b[0m\u001b[0mcnx_kwargs\u001b[0m\u001b[1;33m)\u001b[0m\u001b[1;33m\u001b[0m\u001b[1;33m\u001b[0m\u001b[0m\n\u001b[0m\u001b[0;32m    289\u001b[0m             \u001b[0mself\u001b[0m\u001b[1;33m.\u001b[0m\u001b[0m_cmysql\u001b[0m\u001b[1;33m.\u001b[0m\u001b[0mconverter_str_fallback\u001b[0m \u001b[1;33m=\u001b[0m \u001b[0mself\u001b[0m\u001b[1;33m.\u001b[0m\u001b[0m_converter_str_fallback\u001b[0m\u001b[1;33m\u001b[0m\u001b[1;33m\u001b[0m\u001b[0m\n",
      "\u001b[1;31mMySQLInterfaceError\u001b[0m: Unknown MySQL server host '192.168.1.1:3305' (11001)",
      "\nThe above exception was the direct cause of the following exception:\n",
      "\u001b[1;31mDatabaseError\u001b[0m                             Traceback (most recent call last)",
      "\u001b[1;32m~\\AppData\\Local\\Temp\\ipykernel_23432\\1269289793.py\u001b[0m in \u001b[0;36m<module>\u001b[1;34m\u001b[0m\n\u001b[0;32m      1\u001b[0m \u001b[1;31m# Connexion à la base de données\u001b[0m\u001b[1;33m\u001b[0m\u001b[1;33m\u001b[0m\u001b[0m\n\u001b[1;32m----> 2\u001b[1;33m conn = mysql.connector.connect(user=user_teamprogffxiv, password=password_teamprogffxiv,\n\u001b[0m\u001b[0;32m      3\u001b[0m                               host=host_teamprogffxiv, database=database_name)\n\u001b[0;32m      4\u001b[0m \u001b[1;33m\u001b[0m\u001b[0m\n\u001b[0;32m      5\u001b[0m \u001b[1;31m#creation du cursor\u001b[0m\u001b[1;33m\u001b[0m\u001b[1;33m\u001b[0m\u001b[0m\n",
      "\u001b[1;32mD:\\Anaconda\\lib\\site-packages\\mysql\\connector\\pooling.py\u001b[0m in \u001b[0;36mconnect\u001b[1;34m(*args, **kwargs)\u001b[0m\n\u001b[0;32m    291\u001b[0m \u001b[1;33m\u001b[0m\u001b[0m\n\u001b[0;32m    292\u001b[0m     \u001b[1;32mif\u001b[0m \u001b[0mCMySQLConnection\u001b[0m \u001b[1;32mand\u001b[0m \u001b[1;32mnot\u001b[0m \u001b[0muse_pure\u001b[0m\u001b[1;33m:\u001b[0m\u001b[1;33m\u001b[0m\u001b[1;33m\u001b[0m\u001b[0m\n\u001b[1;32m--> 293\u001b[1;33m         \u001b[1;32mreturn\u001b[0m \u001b[0mCMySQLConnection\u001b[0m\u001b[1;33m(\u001b[0m\u001b[1;33m*\u001b[0m\u001b[0margs\u001b[0m\u001b[1;33m,\u001b[0m \u001b[1;33m**\u001b[0m\u001b[0mkwargs\u001b[0m\u001b[1;33m)\u001b[0m\u001b[1;33m\u001b[0m\u001b[1;33m\u001b[0m\u001b[0m\n\u001b[0m\u001b[0;32m    294\u001b[0m     \u001b[1;32mreturn\u001b[0m \u001b[0mMySQLConnection\u001b[0m\u001b[1;33m(\u001b[0m\u001b[1;33m*\u001b[0m\u001b[0margs\u001b[0m\u001b[1;33m,\u001b[0m \u001b[1;33m**\u001b[0m\u001b[0mkwargs\u001b[0m\u001b[1;33m)\u001b[0m\u001b[1;33m\u001b[0m\u001b[1;33m\u001b[0m\u001b[0m\n\u001b[0;32m    295\u001b[0m \u001b[1;33m\u001b[0m\u001b[0m\n",
      "\u001b[1;32mD:\\Anaconda\\lib\\site-packages\\mysql\\connector\\connection_cext.py\u001b[0m in \u001b[0;36m__init__\u001b[1;34m(self, **kwargs)\u001b[0m\n\u001b[0;32m    116\u001b[0m \u001b[1;33m\u001b[0m\u001b[0m\n\u001b[0;32m    117\u001b[0m         \u001b[1;32mif\u001b[0m \u001b[0mkwargs\u001b[0m\u001b[1;33m:\u001b[0m\u001b[1;33m\u001b[0m\u001b[1;33m\u001b[0m\u001b[0m\n\u001b[1;32m--> 118\u001b[1;33m             \u001b[0mself\u001b[0m\u001b[1;33m.\u001b[0m\u001b[0mconnect\u001b[0m\u001b[1;33m(\u001b[0m\u001b[1;33m**\u001b[0m\u001b[0mkwargs\u001b[0m\u001b[1;33m)\u001b[0m\u001b[1;33m\u001b[0m\u001b[1;33m\u001b[0m\u001b[0m\n\u001b[0m\u001b[0;32m    119\u001b[0m \u001b[1;33m\u001b[0m\u001b[0m\n\u001b[0;32m    120\u001b[0m     \u001b[1;32mdef\u001b[0m \u001b[0m_add_default_conn_attrs\u001b[0m\u001b[1;33m(\u001b[0m\u001b[0mself\u001b[0m\u001b[1;33m)\u001b[0m \u001b[1;33m->\u001b[0m \u001b[1;32mNone\u001b[0m\u001b[1;33m:\u001b[0m\u001b[1;33m\u001b[0m\u001b[1;33m\u001b[0m\u001b[0m\n",
      "\u001b[1;32mD:\\Anaconda\\lib\\site-packages\\mysql\\connector\\abstracts.py\u001b[0m in \u001b[0;36mconnect\u001b[1;34m(self, **kwargs)\u001b[0m\n\u001b[0;32m   1176\u001b[0m \u001b[1;33m\u001b[0m\u001b[0m\n\u001b[0;32m   1177\u001b[0m         \u001b[0mself\u001b[0m\u001b[1;33m.\u001b[0m\u001b[0mdisconnect\u001b[0m\u001b[1;33m(\u001b[0m\u001b[1;33m)\u001b[0m\u001b[1;33m\u001b[0m\u001b[1;33m\u001b[0m\u001b[0m\n\u001b[1;32m-> 1178\u001b[1;33m         \u001b[0mself\u001b[0m\u001b[1;33m.\u001b[0m\u001b[0m_open_connection\u001b[0m\u001b[1;33m(\u001b[0m\u001b[1;33m)\u001b[0m\u001b[1;33m\u001b[0m\u001b[1;33m\u001b[0m\u001b[0m\n\u001b[0m\u001b[0;32m   1179\u001b[0m         \u001b[1;31m# Server does not allow to run any other statement different from ALTER\u001b[0m\u001b[1;33m\u001b[0m\u001b[1;33m\u001b[0m\u001b[0m\n\u001b[0;32m   1180\u001b[0m         \u001b[1;31m# when user's password has been expired.\u001b[0m\u001b[1;33m\u001b[0m\u001b[1;33m\u001b[0m\u001b[0m\n",
      "\u001b[1;32mD:\\Anaconda\\lib\\site-packages\\mysql\\connector\\connection_cext.py\u001b[0m in \u001b[0;36m_open_connection\u001b[1;34m(self)\u001b[0m\n\u001b[0;32m    291\u001b[0m                 \u001b[0mself\u001b[0m\u001b[1;33m.\u001b[0m\u001b[0mconverter\u001b[0m\u001b[1;33m.\u001b[0m\u001b[0mstr_fallback\u001b[0m \u001b[1;33m=\u001b[0m \u001b[0mself\u001b[0m\u001b[1;33m.\u001b[0m\u001b[0m_converter_str_fallback\u001b[0m\u001b[1;33m\u001b[0m\u001b[1;33m\u001b[0m\u001b[0m\n\u001b[0;32m    292\u001b[0m         \u001b[1;32mexcept\u001b[0m \u001b[0mMySQLInterfaceError\u001b[0m \u001b[1;32mas\u001b[0m \u001b[0merr\u001b[0m\u001b[1;33m:\u001b[0m\u001b[1;33m\u001b[0m\u001b[1;33m\u001b[0m\u001b[0m\n\u001b[1;32m--> 293\u001b[1;33m             raise get_mysql_exception(\n\u001b[0m\u001b[0;32m    294\u001b[0m                 \u001b[0mmsg\u001b[0m\u001b[1;33m=\u001b[0m\u001b[0merr\u001b[0m\u001b[1;33m.\u001b[0m\u001b[0mmsg\u001b[0m\u001b[1;33m,\u001b[0m \u001b[0merrno\u001b[0m\u001b[1;33m=\u001b[0m\u001b[0merr\u001b[0m\u001b[1;33m.\u001b[0m\u001b[0merrno\u001b[0m\u001b[1;33m,\u001b[0m \u001b[0msqlstate\u001b[0m\u001b[1;33m=\u001b[0m\u001b[0merr\u001b[0m\u001b[1;33m.\u001b[0m\u001b[0msqlstate\u001b[0m\u001b[1;33m\u001b[0m\u001b[1;33m\u001b[0m\u001b[0m\n\u001b[0;32m    295\u001b[0m             ) from err\n",
      "\u001b[1;31mDatabaseError\u001b[0m: 2005 (HY000): Unknown MySQL server host '192.168.1.1:3305' (11001)"
     ]
    }
   ],
   "source": [
    "# Connexion à la base de données\n",
    "conn = mysql.connector.connect(user=user_teamprogffxiv, password=password_teamprogffxiv,\n",
    "                              host=host_teamprogffxiv, database=database_name)\n",
    "\n",
    "#creation du cursor\n",
    "cursor = conn.cursor()"
   ]
  },
  {
   "cell_type": "code",
   "execution_count": 1,
   "id": "670f0a12",
   "metadata": {},
   "outputs": [
    {
     "ename": "NameError",
     "evalue": "name 'cursor' is not defined",
     "output_type": "error",
     "traceback": [
      "\u001b[1;31m---------------------------------------------------------------------------\u001b[0m",
      "\u001b[1;31mNameError\u001b[0m                                 Traceback (most recent call last)",
      "\u001b[1;32m~\\AppData\\Local\\Temp\\ipykernel_23432\\221002456.py\u001b[0m in \u001b[0;36m<module>\u001b[1;34m\u001b[0m\n\u001b[1;32m----> 1\u001b[1;33m \u001b[0mresult\u001b[0m \u001b[1;33m=\u001b[0m \u001b[0mcursor\u001b[0m\u001b[1;33m.\u001b[0m\u001b[0mexecute\u001b[0m\u001b[1;33m(\u001b[0m\u001b[1;34m\"\"\"Show Databases;\"\"\"\u001b[0m\u001b[1;33m,\u001b[0m \u001b[0melement\u001b[0m\u001b[1;33m)\u001b[0m\u001b[1;33m\u001b[0m\u001b[1;33m\u001b[0m\u001b[0m\n\u001b[0m\u001b[0;32m      2\u001b[0m \u001b[0mprint\u001b[0m\u001b[1;33m(\u001b[0m\u001b[0mresult\u001b[0m\u001b[1;33m)\u001b[0m\u001b[1;33m\u001b[0m\u001b[1;33m\u001b[0m\u001b[0m\n",
      "\u001b[1;31mNameError\u001b[0m: name 'cursor' is not defined"
     ]
    }
   ],
   "source": [
    "result = cursor.execute(\"\"\"Show Databases;\"\"\", element)\n",
    "print(result)"
   ]
  },
  {
   "cell_type": "code",
   "execution_count": null,
   "id": "a6f3db81",
   "metadata": {},
   "outputs": [],
   "source": []
  }
 ],
 "metadata": {
  "kernelspec": {
   "display_name": "Python 3 (ipykernel)",
   "language": "python",
   "name": "python3"
  },
  "language_info": {
   "codemirror_mode": {
    "name": "ipython",
    "version": 3
   },
   "file_extension": ".py",
   "mimetype": "text/x-python",
   "name": "python",
   "nbconvert_exporter": "python",
   "pygments_lexer": "ipython3",
   "version": "3.9.13"
  }
 },
 "nbformat": 4,
 "nbformat_minor": 5
}
